2025-07-30 13:26:11,123 - INFO - Processing page 2: page_02.pdf
2025-07-30 13:26:11,123 - INFO - Starting PDF parsing...
2025-07-30 13:26:16,696 - ERROR - Error processing page 2: HTTPSConnectionPool(host='api.va.landing.ai', port=443): Read timed out. (read timeout=5)
Traceback (most recent call last):
  File "/Users/uli/Desktop/genai_git/landingai-01/lib/python3.11/site-packages/urllib3/connectionpool.py", line 534, in _make_request
    response = conn.getresponse()
               ^^^^^^^^^^^^^^^^^^
  File "/Users/uli/Desktop/genai_git/landingai-01/lib/python3.11/site-packages/urllib3/connection.py", line 565, in getresponse
    httplib_response = super().getresponse()
                       ^^^^^^^^^^^^^^^^^^^^^
  File "/Library/Frameworks/Python.framework/Versions/3.11/lib/python3.11/http/client.py", line 1374, in getresponse
    response.begin()
  File "/Library/Frameworks/Python.framework/Versions/3.11/lib/python3.11/http/client.py", line 318, in begin
    version, status, reason = self._read_status()
                              ^^^^^^^^^^^^^^^^^^^
  File "/Library/Frameworks/Python.framework/Versions/3.11/lib/python3.11/http/client.py", line 279, in _read_status
    line = str(self.fp.readline(_MAXLINE + 1), "iso-8859-1")
               ^^^^^^^^^^^^^^^^^^^^^^^^^^^^^^
  File "/Library/Frameworks/Python.framework/Versions/3.11/lib/python3.11/socket.py", line 706, in readinto
    return self._sock.recv_into(b)
           ^^^^^^^^^^^^^^^^^^^^^^^
  File "/Library/Frameworks/Python.framework/Versions/3.11/lib/python3.11/ssl.py", line 1278, in recv_into
    return self.read(nbytes, buffer)
           ^^^^^^^^^^^^^^^^^^^^^^^^^
  File "/Library/Frameworks/Python.framework/Versions/3.11/lib/python3.11/ssl.py", line 1134, in read
    return self._sslobj.read(len, buffer)
           ^^^^^^^^^^^^^^^^^^^^^^^^^^^^^^
TimeoutError: The read operation timed out

The above exception was the direct cause of the following exception:

Traceback (most recent call last):
  File "/Users/uli/Desktop/genai_git/landingai-01/lib/python3.11/site-packages/requests/adapters.py", line 667, in send
    resp = conn.urlopen(
           ^^^^^^^^^^^^^
  File "/Users/uli/Desktop/genai_git/landingai-01/lib/python3.11/site-packages/urllib3/connectionpool.py", line 841, in urlopen
    retries = retries.increment(
              ^^^^^^^^^^^^^^^^^^
  File "/Users/uli/Desktop/genai_git/landingai-01/lib/python3.11/site-packages/urllib3/util/retry.py", line 474, in increment
    raise reraise(type(error), error, _stacktrace)
          ^^^^^^^^^^^^^^^^^^^^^^^^^^^^^^^^^^^^^^^^
  File "/Users/uli/Desktop/genai_git/landingai-01/lib/python3.11/site-packages/urllib3/util/util.py", line 39, in reraise
    raise value
  File "/Users/uli/Desktop/genai_git/landingai-01/lib/python3.11/site-packages/urllib3/connectionpool.py", line 787, in urlopen
    response = self._make_request(
               ^^^^^^^^^^^^^^^^^^^
  File "/Users/uli/Desktop/genai_git/landingai-01/lib/python3.11/site-packages/urllib3/connectionpool.py", line 536, in _make_request
    self._raise_timeout(err=e, url=url, timeout_value=read_timeout)
  File "/Users/uli/Desktop/genai_git/landingai-01/lib/python3.11/site-packages/urllib3/connectionpool.py", line 367, in _raise_timeout
    raise ReadTimeoutError(
urllib3.exceptions.ReadTimeoutError: HTTPSConnectionPool(host='api.va.landing.ai', port=443): Read timed out. (read timeout=5)

During handling of the above exception, another exception occurred:

Traceback (most recent call last):
  File "/Users/uli/Desktop/genai_git/landingai-01/parse_pdf_pages.py", line 91, in process_single_page
    result = parse(str(page_file))
             ^^^^^^^^^^^^^^^^^^^^^
  File "/Users/uli/Desktop/genai_git/landingai-01/lib/python3.11/site-packages/agentic_doc/parse.py", line 103, in parse
    check_endpoint_and_api_key(
  File "/Users/uli/Desktop/genai_git/landingai-01/lib/python3.11/site-packages/agentic_doc/utils.py", line 33, in check_endpoint_and_api_key
    response = requests.head(endpoint_url, headers=headers, timeout=5)
               ^^^^^^^^^^^^^^^^^^^^^^^^^^^^^^^^^^^^^^^^^^^^^^^^^^^^^^^
  File "/Users/uli/Desktop/genai_git/landingai-01/lib/python3.11/site-packages/requests/api.py", line 100, in head
    return request("head", url, **kwargs)
           ^^^^^^^^^^^^^^^^^^^^^^^^^^^^^^
  File "/Users/uli/Desktop/genai_git/landingai-01/lib/python3.11/site-packages/requests/api.py", line 59, in request
    return session.request(method=method, url=url, **kwargs)
           ^^^^^^^^^^^^^^^^^^^^^^^^^^^^^^^^^^^^^^^^^^^^^^^^^
  File "/Users/uli/Desktop/genai_git/landingai-01/lib/python3.11/site-packages/requests/sessions.py", line 589, in request
    resp = self.send(prep, **send_kwargs)
           ^^^^^^^^^^^^^^^^^^^^^^^^^^^^^^
  File "/Users/uli/Desktop/genai_git/landingai-01/lib/python3.11/site-packages/requests/sessions.py", line 703, in send
    r = adapter.send(request, **kwargs)
        ^^^^^^^^^^^^^^^^^^^^^^^^^^^^^^^
  File "/Users/uli/Desktop/genai_git/landingai-01/lib/python3.11/site-packages/requests/adapters.py", line 713, in send
    raise ReadTimeout(e, request=request)
requests.exceptions.ReadTimeout: HTTPSConnectionPool(host='api.va.landing.ai', port=443): Read timed out. (read timeout=5)
